Workbook

Sheet Läs mig
A1: Valet 2026 i Landskrona – rådata per valdistrikt
A3: Innehåll
A4: KF/RF/RD 2026 | B4: Röster per parti och valdistrikt, slutligt valresultat (kommunfullmäktige, regionfullmäktige Skåne, riksdag). Andelar räknas med formler.
A5: Långtabell | B5: Alla val, distrikt och partier i ett format för pivotering, med 2022 års jämförbara siffror.
A6: Kommuntotaler | B6: Officiella totaler och mandat för Landskrona.
A8: Källa | B8: Valmyndigheten, slutligt valresultat 2026 (resultat.val.se, JSON per valdistrikt), hämtat 2026-10-16.
A9: 2022-siffror | B9: Valmyndighetens omräkning av 2022 års resultat till 2026 års distriktsindelning (fältet "föregående val").
A10: Övr | B10: Övriga partier summerade. Vi = Visionpartiet (lokalt parti, endast kommunvalet).
A11: Uppsamlingsdistrikt | B11: 128200 = sena förtidsröster m.m. Ingår i kommunsumman men saknar geografi och 2022-jämförelse.
A12: Röstberättigade | B12: Antal röstberättigade skiljer mellan valen: i kommun- och regionval röstar även utländska medborgare som varit folkbokförda i tre år; utlandssvenskar röstar bara i riksdagsvalet.
A13: Kontroll | B13: Distriktssummorna stämmer exakt mot Valmyndighetens kommuntotaler för alla tre val.
A14: SCB bakgrund | B14: Bakgrundsvariabler per valdistrikt från SCB:s valanalysverktyg 2026, med korrelationer mot kommunvalsresultatet (formler).
A15: Historik | B15: Valresultat 2006–2026 per valdistrikt (fliken Historik distrikt) och kommuntotaler med formler (Historik kommun). Distriktsgränserna ändras mellan valen.

Sheet SCB bakgrund
A1: Distriktskod | B1: Distrikt | C1: Röstberättigade RD | D1: Valdeltagande RD (%) | E1: Utrikes födda (%) | F1: Låg inkomst, kvintil 1 (%) | G1: Hög inkomst, kvintil 5 (%) | H1: Eftergymnasial ≥3 år (%) | I1: Ålder 18–29 (%) | J1: Ålder 65+ (%) | K1: Utrikes födda (antal) | L1: Bas ursprung | M1: Kvintil 1 (antal) | N1: Kvintil 5 (antal) | O1: Bas inkomst | P1: Eftergymn. (antal) | Q1: Bas utbildning | R1: 18–29 (antal) | S1: 65+ (antal) | T1: Bas ålder
A2: 12820101 | B2: Citadellstaden | C2: 1524 | D2: 76 | E2: 16.49 | F2: 19.43 | G2: 15.01 | H2: 19.05 | I2: 12.01 | J2: 42.17 | K2: 239 | L2: 1449 | M2: 268 | N2: 207 | O2: 1379 | P2: 273 | Q2: 1433 | R2: 174 | S2: 611 | T2: 1449
A3: 12820102 | B3: Fröjdenborg | C3: 1479 | D3: 76 | E3: 25.17 | F3: 26.28 | G3: 12.41 | H3: 17.39 | I3: 14.62 | J3: 35.17 | K3: 360 | L3: 1430 | M3: 360 | N3: 170 | O3: 1370 | P3: 245 | Q3: 1409 | R3: 209 | S3: 503 | T3: 1430
A4: 12820103 | B4: Norra Förstaden | C4: 1625 | D4: 68 | E4: 37.19 | F4: 33.88 | G4: 7.26 | H4: 12.66 | I4: 22.4 | J4: 25.69 | K4: 566 | L4: 1522 | M4: 476 | N4: 102 | O4: 1405 | P4: 190 | Q4: 1501 | R4: 341 | S4: 391 | T4: 1522
A5: 12820104 | B5: Centrum | C5: 1640 | D5: 70 | E5: 26.32 | F5: 27.66 | G5: 9.24 | H5: 15.94 | I5: 18.19 | J5: 28.53 | K5: 405 | L5: 1539 | M5: 401 | N5: 134 | O5: 1450 | P5: 243 | Q5: 1524 | R5: 280 | S5: 439 | T5: 1539
A6: 12820105 | B6: Dammhagen | C6: 1416 | D6: 65 | E6: 51.68 | F6: 41.14 | G6: 5.12 | H6: 11.06 | I6: 24.23 | J6: 21.62 | K6: 691 | L6: 1337 | M6: 490 | N6: 61 | O6: 1191 | P6: 145 | Q6: 1311 | R6: 324 | S6: 289 | T6: 1337
A7: 12820106 | B7: Gustav Adolf | C7: 1530 | D7: 66 | E7: 44.72 | F7: 33.94 | G7: 6.91 | H7: 11.77 | I7: 21.33 | J7: 19.12 | K7: 648 | L7: 1449 | M7: 447 | N7: 91 | O7: 1317 | P7: 166 | Q7: 1410 | R7: 309 | S7: 277 | T7: 1449
A8: 12820107 | B8: S:t Olov | C8: 1091 | D8: 78 | E8: 18.89 | F8: 19.47 | G8: 15.91 | H8: 21.14 | I8: 13.79 | J8: 31.35 | K8: 200 | L8: 1059 | M8: 197 | N8: 161 | O8: 1012 | P8: 222 | Q8: 1050 | R8: 146 | S8: 332 | T8: 1059
A9: 12820108 | B9: Albano | C9: 1597 | D9: 69 | E9: 30.41 | F9: 29.87 | G9: 6.54 | H9: 13.35 | I9: 18.97 | J9: 33.03 | K9: 465 | L9: 1529 | M9: 434 | N9: 95 | O9: 1453 | P9: 201 | Q9: 1506 | R9: 290 | S9: 505 | T9: 1529
A10: 12820109 | B10: Larvi | C10: 1428 | D10: 78 | E10: 17.4 | F10: 23.16 | G10: 11.05 | H10: 14.73 | I10: 13.48 | J10: 31.38 | K10: 244 | L10: 1402 | M10: 308 | N10: 147 | O10: 1330 | P10: 205 | Q10: 1392 | R10: 189 | S10: 440 | T10: 1402
A11: 12820110 | B11: Sandvången | C11: 1001 | D11: 78 | E11: 15.37 | F11: 25.21 | G11: 4.89 | H11: 9.31 | I11: 16.7 | J11: 31.05 | K11: 150 | L11: 976 | M11: 237 | N11: 46 | O11: 940 | P11: 90 | Q11: 967 | R11: 163 | S11: 303 | T11: 976
A12: 12820111 | B12: Helgebröten | C12: 1148 | D12: 78 | E12: 38.52 | F12: 18.35 | G12: 11.93 | H12: 17.2 | I12: 13.7 | J12: 38.43 | K12: 433 | L12: 1124 | M12: 200 | N12: 130 | O12: 1090 | P12: 192 | Q12: 1116 | R12: 154 | S12: 432 | T12: 1124
A13: 12820112 | B13: Norrestad | C13: 1568 | D13: 63 | E13: 56.81 | F13: 36.6 | G13: 3.16 | H13: 10.45 | I13: 23.97 | J13: 15.96 | K13: 801 | L13: 1410 | M13: 463 | N13: 40 | O13: 1265 | P13: 145 | Q13: 1387 | R13: 338 | S13: 225 | T13: 1410
... A27: 12820803 | B27: Glumslöv Södra | C27: 1012 | D27: 87 | E27: 10.26 | F27: 14.16 | G27: 32.37 | H27: 36.21 | I27: 9.44 | J27: 31.18 | K27: 100 | L27: 975 | M27: 133 | N27: 304 | O27: 939 | P27: 352 | Q27: 972 | R27: 92 | S27: 304 | T27: 975
A29: Källa: SCB, valanalysverktyg riksdagsvalet 2026 (ArcGIS-tjänsten Valdistrikt_2026_RD), exporterad 2026-10-16. Andelarna avser röstberättigade i riksdagsvalet; inkomst = 2024 års inkomster, rikets kvintiler.
A31: Korrelation (r) mellan bakgrund och partiets andel i kommunvalet (KF), över 26 distrikt
A32: Bakgrund | B32: S | C32: SD | D32: M | E32: L | F32: V | G32: KD | H32: C | I32: MP
A33: Utrikes födda | B33: =CORREL('SCB bakgrund'!E2:E27,'KF 2026'!R2:R27) -> 0.86427338 | C33: =CORREL('SCB bakgrund'!E2:E27,'KF 2026'!S2:S27) -> -0.18525494 | D33: =CORREL('SCB bakgrund'!E2:E27,'KF 2026'!U2:U27) -> -0.62280783 | E33: =CORREL('SCB bakgrund'!E2:E27,'KF 2026'!Q2:Q27) -> -0.78969465 | F33: =CORREL('SCB bakgrund'!E2:E27,'KF 2026'!T2:T27) -> 0.94717503 | G33: =CORREL('SCB bakgrund'!E2:E27,'KF 2026'!Y2:Y27) -> -0.32204007 | H33: =CORREL('SCB bakgrund'!E2:E27,'KF 2026'!X2:X27) -> -0.52537087 | I33: =CORREL('SCB bakgrund'!E2:E27,'KF 2026'!V2:V27) -> 0.018436148
A34: Låg inkomst | B34: =CORREL('SCB bakgrund'!F2:F27,'KF 2026'!R2:R27) -> 0.83536755 | C34: =CORREL('SCB bakgrund'!F2:F27,'KF 2026'!S2:S27) -> -0.025326643 | D34: =CORREL('SCB bakgrund'!F2:F27,'KF 2026'!U2:U27) -> -0.47099989 | E34: =CORREL('SCB bakgrund'!F2:F27,'KF 2026'!Q2:Q27) -> -0.87867673 | F34: =CORREL('SCB bakgrund'!F2:F27,'KF 2026'!T2:T27) -> 0.93297728 | G34: =CORREL('SCB bakgrund'!F2:F27,'KF 2026'!Y2:Y27) -> -0.22845572 | H34: =CORREL('SCB bakgrund'!F2:F27,'KF 2026'!X2:X27) -> -0.35764204 | I34: =CORREL('SCB bakgrund'!F2:F27,'KF 2026'!V2:V27) -> 0.29125008
A35: Hög inkomst | B35: =CORREL('SCB bakgrund'!G2:G27,'KF 2026'!R2:R27) -> -0.91540004 | C35: =CORREL('SCB bakgrund'!G2:G27,'KF 2026'!S2:S27) -> -0.20505703 | D35: =CORREL('SCB bakgrund'!G2:G27,'KF 2026'!U2:U27) -> 0.66428615 | E35: =CORREL('SCB bakgrund'!G2:G27,'KF 2026'!Q2:Q27) -> 0.81988829 | F35: =CORREL('SCB bakgrund'!G2:G27,'KF 2026'!T2:T27) -> -0.75845674 | G35: =CORREL('SCB bakgrund'!G2:G27,'KF 2026'!Y2:Y27) -> 0.23748305 | H35: =CORREL('SCB bakgrund'!G2:G27,'KF 2026'!X2:X27) -> 0.5886458 | I35: =CORREL('SCB bakgrund'!G2:G27,'KF 2026'!V2:V27) -> -0.010530665
A36: Eftergymnasial | B36: =CORREL('SCB bakgrund'!H2:H27,'KF 2026'!R2:R27) -> -0.84345044 | C36: =CORREL('SCB bakgrund'!H2:H27,'KF 2026'!S2:S27) -> -0.33388556 | D36: =CORREL('SCB bakgrund'!H2:H27,'KF 2026'!U2:U27) -> 0.65576149 | E36: =CORREL('SCB bakgrund'!H2:H27,'KF 2026'!Q2:Q27) -> 0.78565114 | F36: =CORREL('SCB bakgrund'!H2:H27,'KF 2026'!T2:T27) -> -0.71977748 | G36: =CORREL('SCB bakgrund'!H2:H27,'KF 2026'!Y2:Y27) -> 0.20609009 | H36: =CORREL('SCB bakgrund'!H2:H27,'KF 2026'!X2:X27) -> 0.6370434 | I36: =CORREL('SCB bakgrund'!H2:H27,'KF 2026'!V2:V27) -> 0.13479007
A37: 18–29 | B37: =CORREL('SCB bakgrund'!I2:I27,'KF 2026'!R2:R27) -> 0.80882972 | C37: =CORREL('SCB bakgrund'!I2:I27,'KF 2026'!S2:S27) -> 0.093063791 | D37: =CORREL('SCB bakgrund'!I2:I27,'KF 2026'!U2:U27) -> -0.56456784 | E37: =CORREL('SCB bakgrund'!I2:I27,'KF 2026'!Q2:Q27) -> -0.80416265 | F37: =CORREL('SCB bakgrund'!I2:I27,'KF 2026'!T2:T27) -> 0.87583195 | G37: =CORREL('SCB bakgrund'!I2:I27,'KF 2026'!Y2:Y27) -> -0.16423387 | H37: =CORREL('SCB bakgrund'!I2:I27,'KF 2026'!X2:X27) -> -0.52936665 | I37: =CORREL('SCB bakgrund'!I2:I27,'KF 2026'!V2:V27) -> -0.10900223
A38: 65+ | B38: =CORREL('SCB bakgrund'!J2:J27,'KF 2026'!R2:R27) -> -0.24255326 | C38: =CORREL('SCB bakgrund'!J2:J27,'KF 2026'!S2:S27) -> -0.26401708 | D38: =CORREL('SCB bakgrund'!J2:J27,'KF 2026'!U2:U27) -> 0.15834357 | E38: =CORREL('SCB bakgrund'!J2:J27,'KF 2026'!Q2:Q27) -> 0.45300457 | F38: =CORREL('SCB bakgrund'!J2:J27,'KF 2026'!T2:T27) -> -0.52829714 | G38: =CORREL('SCB bakgrund'!J2:J27,'KF 2026'!Y2:Y27) -> -0.10228569 | H38: =CORREL('SCB bakgrund'!J2:J27,'KF 2026'!X2:X27) -> 0.21773633 | I38: =CORREL('SCB bakgrund'!J2:J27,'KF 2026'!V2:V27) -> 0.29550318

Sheet Historik kommun
A1: År | B1: Val | C1: S röster | D1: M röster | E1: SD röster | F1: L röster | G1: V röster | H1: C röster | I1: KD röster | J1: MP röster | K1: Vi röster | L1: Övr röster | M1: Giltiga | N1: S % | O1: M % | P1: SD % | Q1: L % | R1: V % | S1: C % | T1: KD % | U1: MP % | V1: Vi % | W1: Övr % | X1: Röstberättigade | Y1: Röstande | Z1: Valdeltagande %
A2: 2006 | B2: Kommun | C2: =SUMIFS('Historik distrikt'!F$2:F$448,'Historik distrikt'!$A$2:$A$448,$A2,'Historik distrikt'!$B$2:$B$448,$B2) -> 7538 | D2: =SUMIFS('Historik distrikt'!G$2:G$448,'Historik distrikt'!$A$2:$A$448,$A2,'Historik distrikt'!$B$2:$B$448,$B2) -> 3183 | E2: =SUMIFS('Historik distrikt'!H$2:H$448,'Historik distrikt'!$A$2:$A$448,$A2,'Historik distrikt'!$B$2:$B$448,$B2) -> 5250 | F2: =SUMIFS('Historik distrikt'!I$2:I$448,'Historik distrikt'!$A$2:$A$448,$A2,'Historik distrikt'!$B$2:$B$448,$B2) -> 5298 | G2: =SUMIFS('Historik distrikt'!J$2:J$448,'Historik distrikt'!$A$2:$A$448,$A2,'Historik distrikt'!$B$2:$B$448,$B2) -> 823 | H2: =SUMIFS('Historik distrikt'!K$2:K$448,'Historik distrikt'!$A$2:$A$448,$A2,'Historik distrikt'!$B$2:$B$448,$B2) -> 480 | I2: =SUMIFS('Historik distrikt'!L$2:L$448,'Historik distrikt'!$A$2:$A$448,$A2,'Historik distrikt'!$B$2:$B$448,$B2) -> 295 | J2: =SUMIFS('Historik distrikt'!M$2:M$448,'Historik distrikt'!$A$2:$A$448,$A2,'Historik distrikt'!$B$2:$B$448,$B2) -> 534 | ... M2: =SUMIFS('Historik distrikt'!P$2:P$448,'Historik distrikt'!$A$2:$A$448,$A2,'Historik distrikt'!$B$2:$B$448,$B2) -> 23582 | N2: =C2/M2 -> 0.31965058 | O2: =D2/M2 -> 0.13497583 | P2: =E2/M2 -> 0.22262743 | Q2: =F2/M2 -> 0.22466288 | R2: =G2/M2 -> 0.0348995 | S2: =H2/M2 -> 0.020354508 | T2: =I2/M2 -> 0.012509541 | U2: =J2/M2 -> 0.02264439 | V2: =K2/M2 -> 0 | W2: =L2/M2 -> 0.0076753456 | X2: =SUMIFS('Historik distrikt'!S$2:S$448,'Historik distrikt'!$A$2:$A$448,$A2,'Historik distrikt'!$B$2:$B$448,$B2) -> 31056 | Y2: =SUMIFS('Historik distrikt'!R$2:R$448,'Historik distrikt'!$A$2:$A$448,$A2,'Historik distrikt'!$B$2:$B$448,$B2) -> 23841 | Z2: =Y2/X2 -> 0.76767774
A3: 2006 | B3: Region/landsting | C3: =SUMIFS('Historik distrikt'!F$2:F$448,'Historik distrikt'!$A$2:$A$448,$A3,'Historik distrikt'!$B$2:$B$448,$B3) -> 9344 | D3: =SUMIFS('Historik distrikt'!G$2:G$448,'Historik distrikt'!$A$2:$A$448,$A3,'Historik distrikt'!$B$2:$B$448,$B3) -> 4866 | E3: =SUMIFS('Historik distrikt'!H$2:H$448,'Historik distrikt'!$A$2:$A$448,$A3,'Historik distrikt'!$B$2:$B$448,$B3) -> 2596 | F3: =SUMIFS('Historik distrikt'!I$2:I$448,'Historik distrikt'!$A$2:$A$448,$A3,'Historik distrikt'!$B$2:$B$448,$B3) -> 3269 | G3: =SUMIFS('Historik distrikt'!J$2:J$448,'Historik distrikt'!$A$2:$A$448,$A3,'Historik distrikt'!$B$2:$B$448,$B3) -> 962 | H3: =SUMIFS('Historik distrikt'!K$2:K$448,'Historik distrikt'!$A$2:$A$448,$A3,'Historik distrikt'!$B$2:$B$448,$B3) -> 622 | I3: =SUMIFS('Historik distrikt'!L$2:L$448,'Historik distrikt'!$A$2:$A$448,$A3,'Historik distrikt'!$B$2:$B$448,$B3) -> 564 | J3: =SUMIFS('Historik distrikt'!M$2:M$448,'Historik distrikt'!$A$2:$A$448,$A3,'Historik distrikt'!$B$2:$B$448,$B3) -> 601 | ... M3: =SUMIFS('Historik distrikt'!P$2:P$448,'Historik distrikt'!$A$2:$A$448,$A3,'Historik distrikt'!$B$2:$B$448,$B3) -> 23252 | N3: =C3/M3 -> 0.4018579 | O3: =D3/M3 -> 0.20927232 | P3: =E3/M3 -> 0.11164631 | Q3: =F3/M3 -> 0.14059006 | R3: =G3/M3 -> 0.041372785 | S3: =H3/M3 -> 0.026750387 | T3: =I3/M3 -> 0.024255978 | U3: =J3/M3 -> 0.025847239 | V3: =K3/M3 -> 0 | W3: =L3/M3 -> 0.018407019 | X3: =SUMIFS('Historik distrikt'!S$2:S$448,'Historik distrikt'!$A$2:$A$448,$A3,'Historik distrikt'!$B$2:$B$448,$B3) -> 31056 | Y3: =SUMIFS('Historik distrikt'!R$2:R$448,'Historik distrikt'!$A$2:$A$448,$A3,'Historik distrikt'!$B$2:$B$448,$B3) -> 23680 | Z3: =Y3/X3 -> 0.76249356
A4: 2006 | B4: Riksdag | C4: =SUMIFS('Historik distrikt'!F$2:F$448,'Historik distrikt'!$A$2:$A$448,$A4,'Historik distrikt'!$B$2:$B$448,$B4) -> 9398 | D4: =SUMIFS('Historik distrikt'!G$2:G$448,'Historik distrikt'!$A$2:$A$448,$A4,'Historik distrikt'!$B$2:$B$448,$B4) -> 5581 | E4: =SUMIFS('Historik distrikt'!H$2:H$448,'Historik distrikt'!$A$2:$A$448,$A4,'Historik distrikt'!$B$2:$B$448,$B4) -> 1900 | F4: =SUMIFS('Historik distrikt'!I$2:I$448,'Historik distrikt'!$A$2:$A$448,$A4,'Historik distrikt'!$B$2:$B$448,$B4) -> 2809 | G4: =SUMIFS('Historik distrikt'!J$2:J$448,'Historik distrikt'!$A$2:$A$448,$A4,'Historik distrikt'!$B$2:$B$448,$B4) -> 889 | H4: =SUMIFS('Historik distrikt'!K$2:K$448,'Historik distrikt'!$A$2:$A$448,$A4,'Historik distrikt'!$B$2:$B$448,$B4) -> 687 | I4: =SUMIFS('Historik distrikt'!L$2:L$448,'Historik distrikt'!$A$2:$A$448,$A4,'Historik distrikt'!$B$2:$B$448,$B4) -> 633 | J4: =SUMIFS('Historik distrikt'!M$2:M$448,'Historik distrikt'!$A$2:$A$448,$A4,'Historik distrikt'!$B$2:$B$448,$B4) -> 673 | ... M4: =SUMIFS('Historik distrikt'!P$2:P$448,'Historik distrikt'!$A$2:$A$448,$A4,'Historik distrikt'!$B$2:$B$448,$B4) -> 23056 | N4: =C4/M4 -> 0.40761624 | O4: =D4/M4 -> 0.2420628 | P4: =E4/M4 -> 0.08240805 | Q4: =F4/M4 -> 0.1218338 | R4: =G4/M4 -> 0.038558293 | S4: =H4/M4 -> 0.029797016 | T4: =I4/M4 -> 0.027454892 | U4: =J4/M4 -> 0.029189799 | V4: =K4/M4 -> 0 | W4: =L4/M4 -> 0.021079112 | X4: =SUMIFS('Historik distrikt'!S$2:S$448,'Historik distrikt'!$A$2:$A$448,$A4,'Historik distrikt'!$B$2:$B$448,$B4) -> 29228 | Y4: =SUMIFS('Historik distrikt'!R$2:R$448,'Historik distrikt'!$A$2:$A$448,$A4,'Historik distrikt'!$B$2:$B$448,$B4) -> 23369 | Z4: =Y4/X4 -> 0.79954154
A5: 2010 | B5: Kommun | C5: =SUMIFS('Historik distrikt'!F$2:F$448,'Historik distrikt'!$A$2:$A$448,$A5,'Historik distrikt'!$B$2:$B$448,$B5) -> 8493 | D5: =SUMIFS('Historik distrikt'!G$2:G$448,'Historik distrikt'!$A$2:$A$448,$A5,'Historik distrikt'!$B$2:$B$448,$B5) -> 2705 | E5: =SUMIFS('Historik distrikt'!H$2:H$448,'Historik distrikt'!$A$2:$A$448,$A5,'Historik distrikt'!$B$2:$B$448,$B5) -> 3949 | F5: =SUMIFS('Historik distrikt'!I$2:I$448,'Historik distrikt'!$A$2:$A$448,$A5,'Historik distrikt'!$B$2:$B$448,$B5) -> 7479 | G5: =SUMIFS('Historik distrikt'!J$2:J$448,'Historik distrikt'!$A$2:$A$448,$A5,'Historik distrikt'!$B$2:$B$448,$B5) -> 1067 | H5: =SUMIFS('Historik distrikt'!K$2:K$448,'Historik distrikt'!$A$2:$A$448,$A5,'Historik distrikt'!$B$2:$B$448,$B5) -> 326 | I5: =SUMIFS('Historik distrikt'!L$2:L$448,'Historik distrikt'!$A$2:$A$448,$A5,'Historik distrikt'!$B$2:$B$448,$B5) -> 181 | J5: =SUMIFS('Historik distrikt'!M$2:M$448,'Historik distrikt'!$A$2:$A$448,$A5,'Historik distrikt'!$B$2:$B$448,$B5) -> 728 | ... M5: =SUMIFS('Historik distrikt'!P$2:P$448,'Historik distrikt'!$A$2:$A$448,$A5,'Historik distrikt'!$B$2:$B$448,$B5) -> 24958 | N5: =C5/M5 -> 0.34029169 | O5: =D5/M5 -> 0.10838208 | P5: =E5/M5 -> 0.15822582 | Q5: =F5/M5 -> 0.29966343 | R5: =G5/M5 -> 0.042751823 | S5: =H5/M5 -> 0.013061944 | T5: =I5/M5 -> 0.0072521837 | U5: =J5/M5 -> 0.029169004 | V5: =K5/M5 -> 0 | W5: =L5/M5 -> 0.0012020194 | X5: =SUMIFS('Historik distrikt'!S$2:S$448,'Historik distrikt'!$A$2:$A$448,$A5,'Historik distrikt'!$B$2:$B$448,$B5) -> 32426 | Y5: =SUMIFS('Historik distrikt'!R$2:R$448,'Historik distrikt'!$A$2:$A$448,$A5,'Historik distrikt'!$B$2:$B$448,$B5) -> 25188 | Z5: =Y5/X5 -> 0.77678406
A6: 2010 | B6: Region/landsting | C6: =SUMIFS('Historik distrikt'!F$2:F$448,'Historik distrikt'!$A$2:$A$448,$A6,'Historik distrikt'!$B$2:$B$448,$B6) -> 9700 | D6: =SUMIFS('Historik distrikt'!G$2:G$448,'Historik distrikt'!$A$2:$A$448,$A6,'Historik distrikt'!$B$2:$B$448,$B6) -> 5091 | E6: =SUMIFS('Historik distrikt'!H$2:H$448,'Historik distrikt'!$A$2:$A$448,$A6,'Historik distrikt'!$B$2:$B$448,$B6) -> 2609 | F6: =SUMIFS('Historik distrikt'!I$2:I$448,'Historik distrikt'!$A$2:$A$448,$A6,'Historik distrikt'!$B$2:$B$448,$B6) -> 4019 | G6: =SUMIFS('Historik distrikt'!J$2:J$448,'Historik distrikt'!$A$2:$A$448,$A6,'Historik distrikt'!$B$2:$B$448,$B6) -> 1064 | H6: =SUMIFS('Historik distrikt'!K$2:K$448,'Historik distrikt'!$A$2:$A$448,$A6,'Historik distrikt'!$B$2:$B$448,$B6) -> 484 | I6: =SUMIFS('Historik distrikt'!L$2:L$448,'Historik distrikt'!$A$2:$A$448,$A6,'Historik distrikt'!$B$2:$B$448,$B6) -> 443 | J6: =SUMIFS('Historik distrikt'!M$2:M$448,'Historik distrikt'!$A$2:$A$448,$A6,'Historik distrikt'!$B$2:$B$448,$B6) -> 946 | ... M6: =SUMIFS('Historik distrikt'!P$2:P$448,'Historik distrikt'!$A$2:$A$448,$A6,'Historik distrikt'!$B$2:$B$448,$B6) -> 24629 | N6: =C6/M6 -> 0.39384465 | O6: =D6/M6 -> 0.20670754 | P6: =E6/M6 -> 0.10593203 | Q6: =F6/M6 -> 0.16318162 | R6: =G6/M6 -> 0.043201104 | S6: =H6/M6 -> 0.01965163 | T6: =I6/M6 -> 0.017986926 | U6: =J6/M6 -> 0.038410004 | V6: =K6/M6 -> 0 | W6: =L6/M6 -> 0.011084494 | X6: =SUMIFS('Historik distrikt'!S$2:S$448,'Historik distrikt'!$A$2:$A$448,$A6,'Historik distrikt'!$B$2:$B$448,$B6) -> 32426 | Y6: =SUMIFS('Historik distrikt'!R$2:R$448,'Historik distrikt'!$A$2:$A$448,$A6,'Historik distrikt'!$B$2:$B$448,$B6) -> 24995 | Z6: =Y6/X6 -> 0.77083205
A7: 2010 | B7: Riksdag | C7: =SUMIFS('Historik distrikt'!F$2:F$448,'Historik distrikt'!$A$2:$A$448,$A7,'Historik distrikt'!$B$2:$B$448,$B7) -> 8730 | D7: =SUMIFS('Historik distrikt'!G$2:G$448,'Historik distrikt'!$A$2:$A$448,$A7,'Historik distrikt'!$B$2:$B$448,$B7) -> 6877 | E7: =SUMIFS('Historik distrikt'!H$2:H$448,'Historik distrikt'!$A$2:$A$448,$A7,'Historik distrikt'!$B$2:$B$448,$B7) -> 2408 | F7: =SUMIFS('Historik distrikt'!I$2:I$448,'Historik distrikt'!$A$2:$A$448,$A7,'Historik distrikt'!$B$2:$B$448,$B7) -> 2849 | G7: =SUMIFS('Historik distrikt'!J$2:J$448,'Historik distrikt'!$A$2:$A$448,$A7,'Historik distrikt'!$B$2:$B$448,$B7) -> 999 | H7: =SUMIFS('Historik distrikt'!K$2:K$448,'Historik distrikt'!$A$2:$A$448,$A7,'Historik distrikt'!$B$2:$B$448,$B7) -> 605 | I7: =SUMIFS('Historik distrikt'!L$2:L$448,'Historik distrikt'!$A$2:$A$448,$A7,'Historik distrikt'!$B$2:$B$448,$B7) -> 602 | J7: =SUMIFS('Historik distrikt'!M$2:M$448,'Historik distrikt'!$A$2:$A$448,$A7,'Historik distrikt'!$B$2:$B$448,$B7) -> 1058 | ... M7: =SUMIFS('Historik distrikt'!P$2:P$448,'Historik distrikt'!$A$2:$A$448,$A7,'Historik distrikt'!$B$2:$B$448,$B7) -> 24361 | N7: =C7/M7 -> 0.35835967 | O7: =D7/M7 -> 0.28229547 | P7: =E7/M7 -> 0.098846517 | Q7: =F7/M7 -> 0.11694922 | R7: =G7/M7 -> 0.041008169 | S7: =H7/M7 -> 0.024834777 | T7: =I7/M7 -> 0.024711629 | U7: =J7/M7 -> 0.043430073 | V7: =K7/M7 -> 0 | W7: =L7/M7 -> 0.0095644678 | X7: =SUMIFS('Historik distrikt'!S$2:S$448,'Historik distrikt'!$A$2:$A$448,$A7,'Historik distrikt'!$B$2:$B$448,$B7) -> 30056 | Y7: =SUMIFS('Historik distrikt'!R$2:R$448,'Historik distrikt'!$A$2:$A$448,$A7,'Historik distrikt'!$B$2:$B$448,$B7) -> 24599 | Z7: =Y7/X7 -> 0.81843891
A8: 2014 | B8: Kommun | C8: =SUMIFS('Historik distrikt'!F$2:F$448,'Historik distrikt'!$A$2:$A$448,$A8,'Historik distrikt'!$B$2:$B$448,$B8) -> 9037 | D8: =SUMIFS('Historik distrikt'!G$2:G$448,'Historik distrikt'!$A$2:$A$448,$A8,'Historik distrikt'!$B$2:$B$448,$B8) -> 1854 | E8: =SUMIFS('Historik distrikt'!H$2:H$448,'Historik distrikt'!$A$2:$A$448,$A8,'Historik distrikt'!$B$2:$B$448,$B8) -> 4836 | F8: =SUMIFS('Historik distrikt'!I$2:I$448,'Historik distrikt'!$A$2:$A$448,$A8,'Historik distrikt'!$B$2:$B$448,$B8) -> 6668 | G8: =SUMIFS('Historik distrikt'!J$2:J$448,'Historik distrikt'!$A$2:$A$448,$A8,'Historik distrikt'!$B$2:$B$448,$B8) -> 1080 | H8: =SUMIFS('Historik distrikt'!K$2:K$448,'Historik distrikt'!$A$2:$A$448,$A8,'Historik distrikt'!$B$2:$B$448,$B8) -> 602 | I8: =SUMIFS('Historik distrikt'!L$2:L$448,'Historik distrikt'!$A$2:$A$448,$A8,'Historik distrikt'!$B$2:$B$448,$B8) -> 167 | J8: =SUMIFS('Historik distrikt'!M$2:M$448,'Historik distrikt'!$A$2:$A$448,$A8,'Historik distrikt'!$B$2:$B$448,$B8) -> 970 | ... M8: =SUMIFS('Historik distrikt'!P$2:P$448,'Historik distrikt'!$A$2:$A$448,$A8,'Historik distrikt'!$B$2:$B$448,$B8) -> 25905 | N8: =C8/M8 -> 0.34885157 | O8: =D8/M8 -> 0.071569195 | P8: =E8/M8 -> 0.18668211 | Q8: =F8/M8 -> 0.25740205 | R8: =G8/M8 -> 0.041690793 | S8: =H8/M8 -> 0.023238757 | T8: =I8/M8 -> 0.0064466319 | U8: =J8/M8 -> 0.037444509 | V8: =K8/M8 -> 0 | W8: =L8/M8 -> 0.026674387 | X8: =SUMIFS('Historik distrikt'!S$2:S$448,'Historik distrikt'!$A$2:$A$448,$A8,'Historik distrikt'!$B$2:$B$448,$B8) -> 33566 | Y8: =SUMIFS('Historik distrikt'!R$2:R$448,'Historik distrikt'!$A$2:$A$448,$A8,'Historik distrikt'!$B$2:$B$448,$B8) -> 26156 | Z8: =Y8/X8 -> 0.7792409
A9: 2014 | B9: Region/landsting | C9: =SUMIFS('Historik distrikt'!F$2:F$448,'Historik distrikt'!$A$2:$A$448,$A9,'Historik distrikt'!$B$2:$B$448,$B9) -> 10671 | D9: =SUMIFS('Historik distrikt'!G$2:G$448,'Historik distrikt'!$A$2:$A$448,$A9,'Historik distrikt'!$B$2:$B$448,$B9) -> 3546 | E9: =SUMIFS('Historik distrikt'!H$2:H$448,'Historik distrikt'!$A$2:$A$448,$A9,'Historik distrikt'!$B$2:$B$448,$B9) -> 4104 | F9: =SUMIFS('Historik distrikt'!I$2:I$448,'Historik distrikt'!$A$2:$A$448,$A9,'Historik distrikt'!$B$2:$B$448,$B9) -> 2837 | G9: =SUMIFS('Historik distrikt'!J$2:J$448,'Historik distrikt'!$A$2:$A$448,$A9,'Historik distrikt'!$B$2:$B$448,$B9) -> 1239 | H9: =SUMIFS('Historik distrikt'!K$2:K$448,'Historik distrikt'!$A$2:$A$448,$A9,'Historik distrikt'!$B$2:$B$448,$B9) -> 659 | I9: =SUMIFS('Historik distrikt'!L$2:L$448,'Historik distrikt'!$A$2:$A$448,$A9,'Historik distrikt'!$B$2:$B$448,$B9) -> 505 | J9: =SUMIFS('Historik distrikt'!M$2:M$448,'Historik distrikt'!$A$2:$A$448,$A9,'Historik distrikt'!$B$2:$B$448,$B9) -> 1125 | ... M9: =SUMIFS('Historik distrikt'!P$2:P$448,'Historik distrikt'!$A$2:$A$448,$A9,'Historik distrikt'!$B$2:$B$448,$B9) -> 25679 | N9: =C9/M9 -> 0.41555357 | O9: =D9/M9 -> 0.13808949 | P9: =E9/M9 -> 0.15981931 | Q9: =F9/M9 -> 0.11047938 | R9: =G9/M9 -> 0.048249542 | S9: =H9/M9 -> 0.025662993 | T9: =I9/M9 -> 0.019665875 | U9: =J9/M9 -> 0.043810117 | V9: =K9/M9 -> 0 | W9: =L9/M9 -> 0.03866973 | X9: =SUMIFS('Historik distrikt'!S$2:S$448,'Historik distrikt'!$A$2:$A$448,$A9,'Historik distrikt'!$B$2:$B$448,$B9) -> 33566 | Y9: =SUMIFS('Historik distrikt'!R$2:R$448,'Historik distrikt'!$A$2:$A$448,$A9,'Historik distrikt'!$B$2:$B$448,$B9) -> 26041 | Z9: =Y9/X9 -> 0.77581481
A10: 2014 | B10: Riksdag | C10: =SUMIFS('Historik distrikt'!F$2:F$448,'Historik distrikt'!$A$2:$A$448,$A10,'Historik distrikt'!$B$2:$B$448,$B10) -> 9468 | D10: =SUMIFS('Historik distrikt'!G$2:G$448,'Historik distrikt'!$A$2:$A$448,$A10,'Historik distrikt'!$B$2:$B$448,$B10) -> 5044 | E10: =SUMIFS('Historik distrikt'!H$2:H$448,'Historik distrikt'!$A$2:$A$448,$A10,'Historik distrikt'!$B$2:$B$448,$B10) -> 4768 | F10: =SUMIFS('Historik distrikt'!I$2:I$448,'Historik distrikt'!$A$2:$A$448,$A10,'Historik distrikt'!$B$2:$B$448,$B10) -> 1767 | G10: =SUMIFS('Historik distrikt'!J$2:J$448,'Historik distrikt'!$A$2:$A$448,$A10,'Historik distrikt'!$B$2:$B$448,$B10) -> 1063 | H10: =SUMIFS('Historik distrikt'!K$2:K$448,'Historik distrikt'!$A$2:$A$448,$A10,'Historik distrikt'!$B$2:$B$448,$B10) -> 717 | I10: =SUMIFS('Historik distrikt'!L$2:L$448,'Historik distrikt'!$A$2:$A$448,$A10,'Historik distrikt'!$B$2:$B$448,$B10) -> 502 | J10: =SUMIFS('Historik distrikt'!M$2:M$448,'Historik distrikt'!$A$2:$A$448,$A10,'Historik distrikt'!$B$2:$B$448,$B10) -> 1267 | ... M10: =SUMIFS('Historik distrikt'!P$2:P$448,'Historik distrikt'!$A$2:$A$448,$A10,'Historik distrikt'!$B$2:$B$448,$B10) -> 25354 | N10: =C10/M10 -> 0.3734322 | O10: =D10/M10 -> 0.19894297 | P10: =E10/M10 -> 0.18805711 | Q10: =F10/M10 -> 0.069693145 | R10: =G10/M10 -> 0.041926323 | S10: =H10/M10 -> 0.028279561 | T10: =I10/M10 -> 0.019799637 | U10: =J10/M10 -> 0.049972391 | V10: =K10/M10 -> 0 | W10: =L10/M10 -> 0.029896663 | X10: =SUMIFS('Historik distrikt'!S$2:S$448,'Historik distrikt'!$A$2:$A$448,$A10,'Historik distrikt'!$B$2:$B$448,$B10) -> 31279 | Y10: =SUMIFS('Historik distrikt'!R$2:R$448,'Historik distrikt'!$A$2:$A$448,$A10,'Historik distrikt'!$B$2:$B$448,$B10) -> 25606 | Z10: =Y10/X10 -> 0.81863231
A11: 2018 | B11: Kommun | C11: =SUMIFS('Historik distrikt'!F$2:F$448,'Historik distrikt'!$A$2:$A$448,$A11,'Historik distrikt'!$B$2:$B$448,$B11) -> 7652 | D11: =SUMIFS('Historik distrikt'!G$2:G$448,'Historik distrikt'!$A$2:$A$448,$A11,'Historik distrikt'!$B$2:$B$448,$B11) -> 1879 | E11: =SUMIFS('Historik distrikt'!H$2:H$448,'Historik distrikt'!$A$2:$A$448,$A11,'Historik distrikt'!$B$2:$B$448,$B11) -> 5273 | F11: =SUMIFS('Historik distrikt'!I$2:I$448,'Historik distrikt'!$A$2:$A$448,$A11,'Historik distrikt'!$B$2:$B$448,$B11) -> 9377 | G11: =SUMIFS('Historik distrikt'!J$2:J$448,'Historik distrikt'!$A$2:$A$448,$A11,'Historik distrikt'!$B$2:$B$448,$B11) -> 1235 | H11: =SUMIFS('Historik distrikt'!K$2:K$448,'Historik distrikt'!$A$2:$A$448,$A11,'Historik distrikt'!$B$2:$B$448,$B11) -> 598 | I11: =SUMIFS('Historik distrikt'!L$2:L$448,'Historik distrikt'!$A$2:$A$448,$A11,'Historik distrikt'!$B$2:$B$448,$B11) -> 164 | J11: =SUMIFS('Historik distrikt'!M$2:M$448,'Historik distrikt'!$A$2:$A$448,$A11,'Historik distrikt'!$B$2:$B$448,$B11) -> 854 | ... M11: =SUMIFS('Historik distrikt'!P$2:P$448,'Historik distrikt'!$A$2:$A$448,$A11,'Historik distrikt'!$B$2:$B$448,$B11) -> 27385 | N11: =C11/M11 -> 0.27942304 | O11: =D11/M11 -> 0.068614205 | P11: =E11/M11 -> 0.19255067 | Q11: =F11/M11 -> 0.34241373 | R11: =G11/M11 -> 0.045097681 | S11: =H11/M11 -> 0.021836772 | T11: =I11/M11 -> 0.0059886799 | U11: =J11/M11 -> 0.031184955 | V11: =K11/M11 -> 0 | W11: =L11/M11 -> 0.012890268 | X11: =SUMIFS('Historik distrikt'!S$2:S$448,'Historik distrikt'!$A$2:$A$448,$A11,'Historik distrikt'!$B$2:$B$448,$B11) -> 34701 | Y11: =SUMIFS('Historik distrikt'!R$2:R$448,'Historik distrikt'!$A$2:$A$448,$A11,'Historik distrikt'!$B$2:$B$448,$B11) -> 27675 | Z11: =Y11/X11 -> 0.79752745
A12: 2018 | B12: Region/landsting | C12: =SUMIFS('Historik distrikt'!F$2:F$448,'Historik distrikt'!$A$2:$A$448,$A12,'Historik distrikt'!$B$2:$B$448,$B12) -> 9332 | D12: =SUMIFS('Historik distrikt'!G$2:G$448,'Historik distrikt'!$A$2:$A$448,$A12,'Historik distrikt'!$B$2:$B$448,$B12) -> 4250 | E12: =SUMIFS('Historik distrikt'!H$2:H$448,'Historik distrikt'!$A$2:$A$448,$A12,'Historik distrikt'!$B$2:$B$448,$B12) -> 5699 | F12: =SUMIFS('Historik distrikt'!I$2:I$448,'Historik distrikt'!$A$2:$A$448,$A12,'Historik distrikt'!$B$2:$B$448,$B12) -> 2999 | G12: =SUMIFS('Historik distrikt'!J$2:J$448,'Historik distrikt'!$A$2:$A$448,$A12,'Historik distrikt'!$B$2:$B$448,$B12) -> 1472 | H12: =SUMIFS('Historik distrikt'!K$2:K$448,'Historik distrikt'!$A$2:$A$448,$A12,'Historik distrikt'!$B$2:$B$448,$B12) -> 1037 | I12: =SUMIFS('Historik distrikt'!L$2:L$448,'Historik distrikt'!$A$2:$A$448,$A12,'Historik distrikt'!$B$2:$B$448,$B12) -> 1151 | J12: =SUMIFS('Historik distrikt'!M$2:M$448,'Historik distrikt'!$A$2:$A$448,$A12,'Historik distrikt'!$B$2:$B$448,$B12) -> 799 | ... M12: =SUMIFS('Historik distrikt'!P$2:P$448,'Historik distrikt'!$A$2:$A$448,$A12,'Historik distrikt'!$B$2:$B$448,$B12) -> 27086 | N12: =C12/M12 -> 0.34453223 | O12: =D12/M12 -> 0.15690763 | P12: =E12/M12 -> 0.2104039 | Q12: =F12/M12 -> 0.11072141 | R12: =G12/M12 -> 0.054345418 | S12: =H12/M12 -> 0.038285461 | T12: =I12/M12 -> 0.042494277 | U12: =J12/M12 -> 0.029498634 | V12: =K12/M12 -> 0 | W12: =L12/M12 -> 0.012811046 | X12: =SUMIFS('Historik distrikt'!S$2:S$448,'Historik distrikt'!$A$2:$A$448,$A12,'Historik distrikt'!$B$2:$B$448,$B12) -> 34701 | Y12: =SUMIFS('Historik distrikt'!R$2:R$448,'Historik distrikt'!$A$2:$A$448,$A12,'Historik distrikt'!$B$2:$B$448,$B12) -> 27527 | Z12: =Y12/X12 -> 0.79326244
A13: 2018 | B13: Riksdag | C13: =SUMIFS('Historik distrikt'!F$2:F$448,'Historik distrikt'!$A$2:$A$448,$A13,'Historik distrikt'!$B$2:$B$448,$B13) -> 8591 | D13: =SUMIFS('Historik distrikt'!G$2:G$448,'Historik distrikt'!$A$2:$A$448,$A13,'Historik distrikt'!$B$2:$B$448,$B13) -> 4722 | E13: =SUMIFS('Historik distrikt'!H$2:H$448,'Historik distrikt'!$A$2:$A$448,$A13,'Historik distrikt'!$B$2:$B$448,$B13) -> 6800 | F13: =SUMIFS('Historik distrikt'!I$2:I$448,'Historik distrikt'!$A$2:$A$448,$A13,'Historik distrikt'!$B$2:$B$448,$B13) -> 1803 | G13: =SUMIFS('Historik distrikt'!J$2:J$448,'Historik distrikt'!$A$2:$A$448,$A13,'Historik distrikt'!$B$2:$B$448,$B13) -> 1374 | H13: =SUMIFS('Historik distrikt'!K$2:K$448,'Historik distrikt'!$A$2:$A$448,$A13,'Historik distrikt'!$B$2:$B$448,$B13) -> 1196 | I13: =SUMIFS('Historik distrikt'!L$2:L$448,'Historik distrikt'!$A$2:$A$448,$A13,'Historik distrikt'!$B$2:$B$448,$B13) -> 1084 | J13: =SUMIFS('Historik distrikt'!M$2:M$448,'Historik distrikt'!$A$2:$A$448,$A13,'Historik distrikt'!$B$2:$B$448,$B13) -> 854 | ... M13: =SUMIFS('Historik distrikt'!P$2:P$448,'Historik distrikt'!$A$2:$A$448,$A13,'Historik distrikt'!$B$2:$B$448,$B13) -> 26783 | N13: =C13/M13 -> 0.32076317 | O13: =D13/M13 -> 0.17630587 | P13: =E13/M13 -> 0.25389239 | Q13: =F13/M13 -> 0.067318822 | R13: =G13/M13 -> 0.051301199 | S13: =H13/M13 -> 0.044655192 | T13: =I13/M13 -> 0.040473435 | U13: =J13/M13 -> 0.031885898 | V13: =K13/M13 -> 0 | W13: =L13/M13 -> 0.013404025 | X13: =SUMIFS('Historik distrikt'!S$2:S$448,'Historik distrikt'!$A$2:$A$448,$A13,'Historik distrikt'!$B$2:$B$448,$B13) -> 32424 | Y13: =SUMIFS('Historik distrikt'!R$2:R$448,'Historik distrikt'!$A$2:$A$448,$A13,'Historik distrikt'!$B$2:$B$448,$B13) -> 27057 | Z13: =Y13/X13 -> 0.83447446
... A16: 2022 | B16: Riksdag | C16: =SUMIFS('Historik distrikt'!F$2:F$448,'Historik distrikt'!$A$2:$A$448,$A16,'Historik distrikt'!$B$2:$B$448,$B16) -> 8286 | D16: =SUMIFS('Historik distrikt'!G$2:G$448,'Historik distrikt'!$A$2:$A$448,$A16,'Historik distrikt'!$B$2:$B$448,$B16) -> 4623 | E16: =SUMIFS('Historik distrikt'!H$2:H$448,'Historik distrikt'!$A$2:$A$448,$A16,'Historik distrikt'!$B$2:$B$448,$B16) -> 7308 | F16: =SUMIFS('Historik distrikt'!I$2:I$448,'Historik distrikt'!$A$2:$A$448,$A16,'Historik distrikt'!$B$2:$B$448,$B16) -> 1626 | G16: =SUMIFS('Historik distrikt'!J$2:J$448,'Historik distrikt'!$A$2:$A$448,$A16,'Historik distrikt'!$B$2:$B$448,$B16) -> 1275 | H16: =SUMIFS('Historik distrikt'!K$2:K$448,'Historik distrikt'!$A$2:$A$448,$A16,'Historik distrikt'!$B$2:$B$448,$B16) -> 1002 | I16: =SUMIFS('Historik distrikt'!L$2:L$448,'Historik distrikt'!$A$2:$A$448,$A16,'Historik distrikt'!$B$2:$B$448,$B16) -> 954 | J16: =SUMIFS('Historik distrikt'!M$2:M$448,'Historik distrikt'!$A$2:$A$448,$A16,'Historik distrikt'!$B$2:$B$448,$B16) -> 828 | ... M16: =SUMIFS('Historik distrikt'!P$2:P$448,'Historik distrikt'!$A$2:$A$448,$A16,'Historik distrikt'!$B$2:$B$448,$B16) -> 26657 | N16: =C16/M16 -> 0.31083768 | O16: =D16/M16 -> 0.17342537 | P16: =E16/M16 -> 0.27414938 | Q16: =F16/M16 -> 0.060997111 | R16: =G16/M16 -> 0.047829838 | S16: =H16/M16 -> 0.037588626 | T16: =I16/M16 -> 0.035787973 | U16: =J16/M16 -> 0.03106126 | V16: =K16/M16 -> 0 | W16: =L16/M16 -> 0.028322767 | X16: =SUMIFS('Historik distrikt'!S$2:S$448,'Historik distrikt'!$A$2:$A$448,$A16,'Historik distrikt'!$B$2:$B$448,$B16) -> 34011 | Y16: =SUMIFS('Historik distrikt'!R$2:R$448,'Historik distrikt'!$A$2:$A$448,$A16,'Historik distrikt'!$B$2:$B$448,$B16) -> 27032 | Z16: =Y16/X16 -> 0.79480168
A17: 2026 | B17: Kommun | C17: =SUMIFS('Historik distrikt'!F$2:F$448,'Historik distrikt'!$A$2:$A$448,$A17,'Historik distrikt'!$B$2:$B$448,$B17) -> 7336 | D17: =SUMIFS('Historik distrikt'!G$2:G$448,'Historik distrikt'!$A$2:$A$448,$A17,'Historik distrikt'!$B$2:$B$448,$B17) -> 1736 | E17: =SUMIFS('Historik distrikt'!H$2:H$448,'Historik distrikt'!$A$2:$A$448,$A17,'Historik distrikt'!$B$2:$B$448,$B17) -> 4041 | F17: =SUMIFS('Historik distrikt'!I$2:I$448,'Historik distrikt'!$A$2:$A$448,$A17,'Historik distrikt'!$B$2:$B$448,$B17) -> 11486 | G17: =SUMIFS('Historik distrikt'!J$2:J$448,'Historik distrikt'!$A$2:$A$448,$A17,'Historik distrikt'!$B$2:$B$448,$B17) -> 1929 | H17: =SUMIFS('Historik distrikt'!K$2:K$448,'Historik distrikt'!$A$2:$A$448,$A17,'Historik distrikt'!$B$2:$B$448,$B17) -> 357 | I17: =SUMIFS('Historik distrikt'!L$2:L$448,'Historik distrikt'!$A$2:$A$448,$A17,'Historik distrikt'!$B$2:$B$448,$B17) -> 300 | J17: =SUMIFS('Historik distrikt'!M$2:M$448,'Historik distrikt'!$A$2:$A$448,$A17,'Historik distrikt'!$B$2:$B$448,$B17) -> 1066 | ... M17: =SUMIFS('Historik distrikt'!P$2:P$448,'Historik distrikt'!$A$2:$A$448,$A17,'Historik distrikt'!$B$2:$B$448,$B17) -> 28792 | N17: =C17/M17 -> 0.254793 | O17: =D17/M17 -> 0.060294526 | P17: =E17/M17 -> 0.14035149 | Q17: =F17/M17 -> 0.39893026 | R17: =G17/M17 -> 0.066997777 | S17: =H17/M17 -> 0.012399278 | T17: =I17/M17 -> 0.010419561 | U17: =J17/M17 -> 0.037024173 | V17: =K17/M17 -> 0.015108363 | W17: =L17/M17 -> 0.0036815782 | X17: 37352 | Z17: 0.78
A18: 2026 | B18: Region/landsting | C18: =SUMIFS('Historik distrikt'!F$2:F$448,'Historik distrikt'!$A$2:$A$448,$A18,'Historik distrikt'!$B$2:$B$448,$B18) -> 9403 | D18: =SUMIFS('Historik distrikt'!G$2:G$448,'Historik distrikt'!$A$2:$A$448,$A18,'Historik distrikt'!$B$2:$B$448,$B18) -> 5049 | E18: =SUMIFS('Historik distrikt'!H$2:H$448,'Historik distrikt'!$A$2:$A$448,$A18,'Historik distrikt'!$B$2:$B$448,$B18) -> 5137 | F18: =SUMIFS('Historik distrikt'!I$2:I$448,'Historik distrikt'!$A$2:$A$448,$A18,'Historik distrikt'!$B$2:$B$448,$B18) -> 3146 | G18: =SUMIFS('Historik distrikt'!J$2:J$448,'Historik distrikt'!$A$2:$A$448,$A18,'Historik distrikt'!$B$2:$B$448,$B18) -> 2563 | H18: =SUMIFS('Historik distrikt'!K$2:K$448,'Historik distrikt'!$A$2:$A$448,$A18,'Historik distrikt'!$B$2:$B$448,$B18) -> 686 | I18: =SUMIFS('Historik distrikt'!L$2:L$448,'Historik distrikt'!$A$2:$A$448,$A18,'Historik distrikt'!$B$2:$B$448,$B18) -> 1341 | J18: =SUMIFS('Historik distrikt'!M$2:M$448,'Historik distrikt'!$A$2:$A$448,$A18,'Historik distrikt'!$B$2:$B$448,$B18) -> 934 | ... M18: =SUMIFS('Historik distrikt'!P$2:P$448,'Historik distrikt'!$A$2:$A$448,$A18,'Historik distrikt'!$B$2:$B$448,$B18) -> 28457 | N18: =C18/M18 -> 0.33042837 | O18: =D18/M18 -> 0.17742559 | P18: =E18/M18 -> 0.18051797 | Q18: =F18/M18 -> 0.11055276 | R18: =G18/M18 -> 0.090065713 | S18: =H18/M18 -> 0.024106547 | T18: =I18/M18 -> 0.047123731 | U18: =J18/M18 -> 0.03282145 | V18: =K18/M18 -> 0 | W18: =L18/M18 -> 0.0069578663 | X18: 37352 | Z18: 0.7755
A19: 2026 | B19: Riksdag | C19: =SUMIFS('Historik distrikt'!F$2:F$448,'Historik distrikt'!$A$2:$A$448,$A19,'Historik distrikt'!$B$2:$B$448,$B19) -> 8559 | D19: =SUMIFS('Historik distrikt'!G$2:G$448,'Historik distrikt'!$A$2:$A$448,$A19,'Historik distrikt'!$B$2:$B$448,$B19) -> 4845 | E19: =SUMIFS('Historik distrikt'!H$2:H$448,'Historik distrikt'!$A$2:$A$448,$A19,'Historik distrikt'!$B$2:$B$448,$B19) -> 6466 | F19: =SUMIFS('Historik distrikt'!I$2:I$448,'Historik distrikt'!$A$2:$A$448,$A19,'Historik distrikt'!$B$2:$B$448,$B19) -> 2394 | G19: =SUMIFS('Historik distrikt'!J$2:J$448,'Historik distrikt'!$A$2:$A$448,$A19,'Historik distrikt'!$B$2:$B$448,$B19) -> 2454 | H19: =SUMIFS('Historik distrikt'!K$2:K$448,'Historik distrikt'!$A$2:$A$448,$A19,'Historik distrikt'!$B$2:$B$448,$B19) -> 1098 | I19: =SUMIFS('Historik distrikt'!L$2:L$448,'Historik distrikt'!$A$2:$A$448,$A19,'Historik distrikt'!$B$2:$B$448,$B19) -> 1099 | J19: =SUMIFS('Historik distrikt'!M$2:M$448,'Historik distrikt'!$A$2:$A$448,$A19,'Historik distrikt'!$B$2:$B$448,$B19) -> 1041 | ... M19: =SUMIFS('Historik distrikt'!P$2:P$448,'Historik distrikt'!$A$2:$A$448,$A19,'Historik distrikt'!$B$2:$B$448,$B19) -> 28299 | N19: =C19/M19 -> 0.30244885 | O19: =D19/M19 -> 0.17120746 | P19: =E19/M19 -> 0.22848864 | Q19: =F19/M19 -> 0.084596629 | R19: =G19/M19 -> 0.086716845 | S19: =H19/M19 -> 0.038799958 | T19: =I19/M19 -> 0.038835295 | U19: =J19/M19 -> 0.036785752 | V19: =K19/M19 -> 0 | W19: =L19/M19 -> 0.01212057 | X19: 35507 | Z19: 0.8051
A21: Källa: Valmyndigheten (historik.val.se, resultat.val.se), slutligt resultat per valdistrikt. FP redovisas som L. 2006 innehåller en beräknad rad för röster utanför distrikten. 2026: röstberättigade och valdeltagande enligt Valmyndighetens kommuntotal (röstande per distrikt saknas i underlaget).

Sheet KF 2026
A1: Distriktskod | B1: Distrikt | C1: Röstberättigade | D1: Valdeltagande 2026 (%) | E1: Valdeltagande 2022 (%) | F1: L | G1: S | H1: SD | I1: V | J1: M | K1: MP | L1: Vi | M1: C | N1: KD | O1: Övr | P1: Giltiga röster | Q1: L % | R1: S % | S1: SD % | T1: V % | U1: M % | V1: MP % | W1: Vi % | X1: C % | Y1: KD % | Z1: Övr %
A2: 12820101 | B2: Citadellstaden | C2: 1544 | D2: 75.71 | E2: 80.38 | F2: 541 | G2: 249 | H2: 189 | I2: 57 | J2: 56 | K2: 29 | L2: 12 | M2: 13 | N2: 13 | O2: 2 | P2: =SUM(F2:O2) -> 1161 | Q2: =IFERROR(F2/P2,0) -> 0.46597761 | R2: =IFERROR(G2/P2,0) -> 0.21447028 | S2: =IFERROR(H2/P2,0) -> 0.1627907 | T2: =IFERROR(I2/P2,0) -> 0.049095607 | U2: =IFERROR(J2/P2,0) -> 0.048234281 | V2: =IFERROR(K2/P2,0) -> 0.024978467 | W2: =IFERROR(L2/P2,0) -> 0.010335917 | X2: =IFERROR(M2/P2,0) -> 0.011197244 | Y2: =IFERROR(N2/P2,0) -> 0.011197244 | Z2: =IFERROR(O2/P2,0) -> 0.0017226529
A3: 12820102 | B3: Fröjdenborg | C3: 1518 | D3: 75.43 | E3: 71.04 | F3: 433 | G3: 291 | H3: 171 | I3: 96 | J3: 47 | K3: 51 | L3: 25 | M3: 6 | N3: 8 | O3: 2 | P3: =SUM(F3:O3) -> 1130 | Q3: =IFERROR(F3/P3,0) -> 0.38318584 | R3: =IFERROR(G3/P3,0) -> 0.25752212 | S3: =IFERROR(H3/P3,0) -> 0.15132743 | T3: =IFERROR(I3/P3,0) -> 0.084955752 | U3: =IFERROR(J3/P3,0) -> 0.04159292 | V3: =IFERROR(K3/P3,0) -> 0.045132743 | W3: =IFERROR(L3/P3,0) -> 0.022123894 | X3: =IFERROR(M3/P3,0) -> 0.0053097345 | Y3: =IFERROR(N3/P3,0) -> 0.007079646 | Z3: =IFERROR(O3/P3,0) -> 0.0017699115
A4: 12820103 | B4: Norra Förstaden | C4: 1754 | D4: 67.1 | E4: 63.41 | F4: 280 | G4: 433 | H4: 155 | I4: 140 | J4: 50 | K4: 51 | L4: 13 | M4: 12 | N4: 15 | O4: 8 | P4: =SUM(F4:O4) -> 1157 | Q4: =IFERROR(F4/P4,0) -> 0.24200519 | R4: =IFERROR(G4/P4,0) -> 0.37424373 | S4: =IFERROR(H4/P4,0) -> 0.13396716 | T4: =IFERROR(I4/P4,0) -> 0.12100259 | U4: =IFERROR(J4/P4,0) -> 0.043215212 | V4: =IFERROR(K4/P4,0) -> 0.044079516 | W4: =IFERROR(L4/P4,0) -> 0.011235955 | X4: =IFERROR(M4/P4,0) -> 0.010371651 | Y4: =IFERROR(N4/P4,0) -> 0.012964564 | Z4: =IFERROR(O4/P4,0) -> 0.0069144339
A5: 12820104 | B5: Centrum | C5: 1717 | D5: 68.96 | E5: 62.6 | F5: 411 | G5: 322 | H5: 183 | I5: 101 | J5: 58 | K5: 50 | L5: 9 | M5: 12 | N5: 16 | O5: 1 | P5: =SUM(F5:O5) -> 1163 | Q5: =IFERROR(F5/P5,0) -> 0.35339639 | R5: =IFERROR(G5/P5,0) -> 0.27687016 | S5: =IFERROR(H5/P5,0) -> 0.15735168 | T5: =IFERROR(I5/P5,0) -> 0.086844368 | U5: =IFERROR(J5/P5,0) -> 0.049871023 | V5: =IFERROR(K5/P5,0) -> 0.042992261 | W5: =IFERROR(L5/P5,0) -> 0.0077386071 | X5: =IFERROR(M5/P5,0) -> 0.010318143 | Y5: =IFERROR(N5/P5,0) -> 0.013757524 | Z5: =IFERROR(O5/P5,0) -> 0.00085984523
A6: 12820105 | B6: Dammhagen | C6: 1649 | D6: 61.67 | E6: 54.74 | F6: 152 | G6: 413 | H6: 107 | I6: 182 | J6: 52 | K6: 47 | L6: 34 | M6: 6 | N6: 7 | O6: 5 | P6: =SUM(F6:O6) -> 1005 | Q6: =IFERROR(F6/P6,0) -> 0.15124378 | R6: =IFERROR(G6/P6,0) -> 0.41094527 | S6: =IFERROR(H6/P6,0) -> 0.10646766 | T6: =IFERROR(I6/P6,0) -> 0.18109453 | U6: =IFERROR(J6/P6,0) -> 0.051741294 | V6: =IFERROR(K6/P6,0) -> 0.046766169 | W6: =IFERROR(L6/P6,0) -> 0.033830846 | X6: =IFERROR(M6/P6,0) -> 0.0059701493 | Y6: =IFERROR(N6/P6,0) -> 0.0069651741 | Z6: =IFERROR(O6/P6,0) -> 0.0049751244
A7: 12820106 | B7: Gustav Adolf | C7: 1795 | D7: 59.67 | E7: 55.54 | F7: 266 | G7: 391 | H7: 117 | I7: 140 | J7: 31 | K7: 49 | L7: 37 | M7: 5 | N7: 15 | O7: 8 | P7: =SUM(F7:O7) -> 1059 | Q7: =IFERROR(F7/P7,0) -> 0.25118036 | R7: =IFERROR(G7/P7,0) -> 0.36921624 | S7: =IFERROR(H7/P7,0) -> 0.11048159 | T7: =IFERROR(I7/P7,0) -> 0.13220019 | U7: =IFERROR(J7/P7,0) -> 0.029272899 | V7: =IFERROR(K7/P7,0) -> 0.046270066 | W7: =IFERROR(L7/P7,0) -> 0.034938621 | X7: =IFERROR(M7/P7,0) -> 0.0047214353 | Y7: =IFERROR(N7/P7,0) -> 0.014164306 | Z7: =IFERROR(O7/P7,0) -> 0.0075542965
A8: 12820107 | B8: S:t Olov | C8: 1138 | D8: 76.8 | E8: 75.9 | F8: 397 | G8: 210 | H8: 113 | I8: 48 | J8: 28 | K8: 38 | L8: 3 | M8: 16 | N8: 9 | O8: 2 | P8: =SUM(F8:O8) -> 864 | Q8: =IFERROR(F8/P8,0) -> 0.45949074 | R8: =IFERROR(G8/P8,0) -> 0.24305556 | S8: =IFERROR(H8/P8,0) -> 0.13078704 | T8: =IFERROR(I8/P8,0) -> 0.055555556 | U8: =IFERROR(J8/P8,0) -> 0.032407407 | V8: =IFERROR(K8/P8,0) -> 0.043981481 | W8: =IFERROR(L8/P8,0) -> 0.0034722222 | X8: =IFERROR(M8/P8,0) -> 0.018518519 | Y8: =IFERROR(N8/P8,0) -> 0.010416667 | Z8: =IFERROR(O8/P8,0) -> 0.0023148148
A9: 12820108 | B9: Albano | C9: 1725 | D9: 66.14 | E9: 62.49 | F9: 326 | G9: 369 | H9: 188 | I9: 91 | J9: 42 | K9: 50 | L9: 17 | M9: 15 | N9: 16 | O9: 4 | P9: =SUM(F9:O9) -> 1118 | Q9: =IFERROR(F9/P9,0) -> 0.29159213 | R9: =IFERROR(G9/P9,0) -> 0.33005367 | S9: =IFERROR(H9/P9,0) -> 0.16815742 | T9: =IFERROR(I9/P9,0) -> 0.081395349 | U9: =IFERROR(J9/P9,0) -> 0.037567084 | V9: =IFERROR(K9/P9,0) -> 0.044722719 | W9: =IFERROR(L9/P9,0) -> 0.015205725 | X9: =IFERROR(M9/P9,0) -> 0.013416816 | Y9: =IFERROR(N9/P9,0) -> 0.01431127 | Z9: =IFERROR(O9/P9,0) -> 0.0035778175
A10: 12820109 | B10: Larvi | C10: 1510 | D10: 75.03 | E10: 73.33 | F10: 423 | G10: 308 | H10: 190 | I10: 64 | J10: 53 | K10: 42 | L10: 11 | M10: 9 | N10: 10 | O10: 4 | P10: =SUM(F10:O10) -> 1114 | Q10: =IFERROR(F10/P10,0) -> 0.37971275 | R10: =IFERROR(G10/P10,0) -> 0.27648115 | S10: =IFERROR(H10/P10,0) -> 0.17055655 | T10: =IFERROR(I10/P10,0) -> 0.057450628 | U10: =IFERROR(J10/P10,0) -> 0.047576302 | V10: =IFERROR(K10/P10,0) -> 0.037701975 | W10: =IFERROR(L10/P10,0) -> 0.0098743268 | X10: =IFERROR(M10/P10,0) -> 0.0080789946 | Y10: =IFERROR(N10/P10,0) -> 0.0089766607 | Z10: =IFERROR(O10/P10,0) -> 0.0035906643
A11: 12820110 | B11: Sandvången | C11: 1040 | D11: 76.44 | E11: 76.52 | F11: 228 | G11: 255 | H11: 184 | I11: 45 | J11: 33 | K11: 25 | L11: 6 | M11: 2 | N11: 5 | O11: 4 | P11: =SUM(F11:O11) -> 787 | Q11: =IFERROR(F11/P11,0) -> 0.28970775 | R11: =IFERROR(G11/P11,0) -> 0.32401525 | S11: =IFERROR(H11/P11,0) -> 0.23379924 | T11: =IFERROR(I11/P11,0) -> 0.057179161 | U11: =IFERROR(J11/P11,0) -> 0.041931385 | V11: =IFERROR(K11/P11,0) -> 0.031766201 | W11: =IFERROR(L11/P11,0) -> 0.0076238882 | X11: =IFERROR(M11/P11,0) -> 0.0025412961 | Y11: =IFERROR(N11/P11,0) -> 0.0063532402 | Z11: =IFERROR(O11/P11,0) -> 0.0050825921
A12: 12820111 | B12: Helgebröten | C12: 1161 | D12: 78.04 | E12: 80.68 | F12: 343 | G12: 338 | H12: 87 | I12: 55 | J12: 25 | K12: 31 | L12: 11 | M12: 3 | N12: 7 | O12: 1 | P12: =SUM(F12:O12) -> 901 | Q12: =IFERROR(F12/P12,0) -> 0.38068812 | R12: =IFERROR(G12/P12,0) -> 0.37513873 | S12: =IFERROR(H12/P12,0) -> 0.096559378 | T12: =IFERROR(I12/P12,0) -> 0.061043285 | U12: =IFERROR(J12/P12,0) -> 0.027746948 | V12: =IFERROR(K12/P12,0) -> 0.034406215 | W12: =IFERROR(L12/P12,0) -> 0.012208657 | X12: =IFERROR(M12/P12,0) -> 0.0033296337 | Y12: =IFERROR(N12/P12,0) -> 0.0077691454 | Z12: =IFERROR(O12/P12,0) -> 0.0011098779
A13: 12820112 | B13: Norrestad | C13: 1742 | D13: 60.73 | E13: 54.71 | F13: 104 | G13: 427 | H13: 120 | I13: 213 | J13: 27 | K13: 31 | L13: 117 | M13: 7 | N13: 4 | O13: 4 | P13: =SUM(F13:O13) -> 1054 | Q13: =IFERROR(F13/P13,0) -> 0.098671727 | R13: =IFERROR(G13/P13,0) -> 0.40512334 | S13: =IFERROR(H13/P13,0) -> 0.11385199 | T13: =IFERROR(I13/P13,0) -> 0.20208729 | U13: =IFERROR(J13/P13,0) -> 0.025616698 | V13: =IFERROR(K13/P13,0) -> 0.029411765 | W13: =IFERROR(L13/P13,0) -> 0.11100569 | X13: =IFERROR(M13/P13,0) -> 0.0066413662 | Y13: =IFERROR(N13/P13,0) -> 0.0037950664 | Z13: =IFERROR(O13/P13,0) -> 0.0037950664
... A27: 12820803 | B27: Glumslöv Södra | C27: 1001 | D27: 88.41 | E27: 88.76 | F27: 456 | G27: 134 | H27: 108 | I27: 14 | J27: 92 | K27: 29 | L27: 2 | M27: 26 | N27: 15 | O27: 0 | P27: =SUM(F27:O27) -> 876 | Q27: =IFERROR(F27/P27,0) -> 0.52054795 | R27: =IFERROR(G27/P27,0) -> 0.15296804 | S27: =IFERROR(H27/P27,0) -> 0.12328767 | T27: =IFERROR(I27/P27,0) -> 0.015981735 | U27: =IFERROR(J27/P27,0) -> 0.10502283 | V27: =IFERROR(K27/P27,0) -> 0.033105023 | W27: =IFERROR(L27/P27,0) -> 0.002283105 | X27: =IFERROR(M27/P27,0) -> 0.029680365 | Y27: =IFERROR(N27/P27,0) -> 0.017123288 | Z27: =IFERROR(O27/P27,0) -> 0
A28: 128200 | B28: Uppsamlingsdistrikt 00 | F28: 265 | G28: 204 | H28: 112 | I28: 69 | J28: 68 | K28: 35 | L28: 7 | M28: 13 | N28: 11 | O28: 3 | P28: =SUM(F28:O28) -> 787 | Q28: =IFERROR(F28/P28,0) -> 0.33672173 | R28: =IFERROR(G28/P28,0) -> 0.2592122 | S28: =IFERROR(H28/P28,0) -> 0.14231258 | T28: =IFERROR(I28/P28,0) -> 0.087674714 | U28: =IFERROR(J28/P28,0) -> 0.086404066 | V28: =IFERROR(K28/P28,0) -> 0.044472681 | W28: =IFERROR(L28/P28,0) -> 0.0088945362 | X28: =IFERROR(M28/P28,0) -> 0.016518424 | Y28: =IFERROR(N28/P28,0) -> 0.013977128 | Z28: =IFERROR(O28/P28,0) -> 0.0038119441
B29: Landskrona totalt | C29: =SUM(C2:C28) -> 37352 | F29: =SUM(F2:F28) -> 11486 | G29: =SUM(G2:G28) -> 7336 | H29: =SUM(H2:H28) -> 4041 | I29: =SUM(I2:I28) -> 1929 | J29: =SUM(J2:J28) -> 1736 | K29: =SUM(K2:K28) -> 1066 | L29: =SUM(L2:L28) -> 435 | M29: =SUM(M2:M28) -> 357 | ... P29: =SUM(P2:P28) -> 28792 | Q29: =F29/P29 -> 0.39893026 | R29: =G29/P29 -> 0.254793 | S29: =H29/P29 -> 0.14035149 | T29: =I29/P29 -> 0.066997777 | U29: =J29/P29 -> 0.060294526 | V29: =K29/P29 -> 0.037024173 | W29: =L29/P29 -> 0.015108363 | X29: =M29/P29 -> 0.012399278 | Y29: =N29/P29 -> 0.010419561 | Z29: =O29/P29 -> 0.0036815782

Sheet RF 2026
A1: Distriktskod | B1: Distrikt | C1: Röstberättigade | D1: Valdeltagande 2026 (%) | E1: Valdeltagande 2022 (%) | F1: S | G1: SD | H1: M | I1: L | J1: V | K1: KD | L1: MP | M1: C | N1: Övr | O1: Giltiga röster | P1: S % | Q1: SD % | R1: M % | S1: L % | T1: V % | U1: KD % | V1: MP % | W1: C % | X1: Övr %
A2: 12820101 | B2: Citadellstaden | C2: 1544 | D2: 75.06 | E2: 79.7 | F2: 335 | G2: 238 | H2: 203 | I2: 153 | J2: 75 | K2: 67 | L2: 31 | M2: 27 | N2: 12 | O2: =SUM(F2:N2) -> 1141 | P2: =IFERROR(F2/O2,0) -> 0.2936021 | Q2: =IFERROR(G2/O2,0) -> 0.20858896 | R2: =IFERROR(H2/O2,0) -> 0.17791411 | S2: =IFERROR(I2/O2,0) -> 0.1340929 | T2: =IFERROR(J2/O2,0) -> 0.065731814 | U2: =IFERROR(K2/O2,0) -> 0.058720421 | V2: =IFERROR(L2/O2,0) -> 0.02716915 | W2: =IFERROR(M2/O2,0) -> 0.023663453 | X2: =IFERROR(N2/O2,0) -> 0.01051709
A3: 12820102 | B3: Fröjdenborg | C3: 1518 | D3: 74.9 | E3: 70.52 | F3: 369 | G3: 216 | H3: 155 | I3: 129 | J3: 128 | K3: 53 | L3: 42 | M3: 20 | N3: 6 | O3: =SUM(F3:N3) -> 1118 | P3: =IFERROR(F3/O3,0) -> 0.33005367 | Q3: =IFERROR(G3/O3,0) -> 0.19320215 | R3: =IFERROR(H3/O3,0) -> 0.13864043 | S3: =IFERROR(I3/O3,0) -> 0.11538462 | T3: =IFERROR(J3/O3,0) -> 0.11449016 | U3: =IFERROR(K3/O3,0) -> 0.047406082 | V3: =IFERROR(L3/O3,0) -> 0.037567084 | W3: =IFERROR(M3/O3,0) -> 0.017889088 | X3: =IFERROR(N3/O3,0) -> 0.0053667263
A4: 12820103 | B4: Norra Förstaden | C4: 1754 | D4: 66.36 | E4: 63 | F4: 472 | G4: 183 | H4: 115 | I4: 91 | J4: 171 | K4: 36 | L4: 42 | M4: 19 | N4: 14 | O4: =SUM(F4:N4) -> 1143 | P4: =IFERROR(F4/O4,0) -> 0.41294838 | Q4: =IFERROR(G4/O4,0) -> 0.16010499 | R4: =IFERROR(H4/O4,0) -> 0.10061242 | S4: =IFERROR(I4/O4,0) -> 0.079615048 | T4: =IFERROR(J4/O4,0) -> 0.1496063 | U4: =IFERROR(K4/O4,0) -> 0.031496063 | V4: =IFERROR(L4/O4,0) -> 0.036745407 | W4: =IFERROR(M4/O4,0) -> 0.016622922 | X4: =IFERROR(N4/O4,0) -> 0.012248469
A5: 12820104 | B5: Centrum | C5: 1717 | D5: 68.26 | E5: 62.67 | F5: 388 | G5: 238 | H5: 145 | I5: 130 | J5: 120 | K5: 41 | L5: 52 | M5: 24 | N5: 8 | O5: =SUM(F5:N5) -> 1146 | P5: =IFERROR(F5/O5,0) -> 0.33856894 | Q5: =IFERROR(G5/O5,0) -> 0.20767888 | R5: =IFERROR(H5/O5,0) -> 0.12652705 | S5: =IFERROR(I5/O5,0) -> 0.11343805 | T5: =IFERROR(J5/O5,0) -> 0.10471204 | U5: =IFERROR(K5/O5,0) -> 0.035776614 | V5: =IFERROR(L5/O5,0) -> 0.045375218 | W5: =IFERROR(M5/O5,0) -> 0.020942408 | X5: =IFERROR(N5/O5,0) -> 0.0069808028
A6: 12820105 | B6: Dammhagen | C6: 1649 | D6: 61.43 | E6: 53.91 | F6: 459 | G6: 123 | H6: 85 | I6: 51 | J6: 226 | K6: 12 | L6: 25 | M6: 14 | N6: 5 | O6: =SUM(F6:N6) -> 1000 | P6: =IFERROR(F6/O6,0) -> 0.459 | Q6: =IFERROR(G6/O6,0) -> 0.123 | R6: =IFERROR(H6/O6,0) -> 0.085 | S6: =IFERROR(I6/O6,0) -> 0.051 | T6: =IFERROR(J6/O6,0) -> 0.226 | U6: =IFERROR(K6/O6,0) -> 0.012 | V6: =IFERROR(L6/O6,0) -> 0.025 | W6: =IFERROR(M6/O6,0) -> 0.014 | X6: =IFERROR(N6/O6,0) -> 0.005
A7: 12820106 | B7: Gustav Adolf | C7: 1795 | D7: 59.83 | E7: 54.98 | F7: 463 | G7: 158 | H7: 99 | I7: 71 | J7: 190 | K7: 33 | L7: 26 | M7: 12 | N7: 11 | O7: =SUM(F7:N7) -> 1063 | P7: =IFERROR(F7/O7,0) -> 0.43555974 | Q7: =IFERROR(G7/O7,0) -> 0.14863594 | R7: =IFERROR(H7/O7,0) -> 0.093132643 | S7: =IFERROR(I7/O7,0) -> 0.066792098 | T7: =IFERROR(J7/O7,0) -> 0.17873942 | U7: =IFERROR(K7/O7,0) -> 0.031044214 | V7: =IFERROR(L7/O7,0) -> 0.024459078 | W7: =IFERROR(M7/O7,0) -> 0.011288805 | X7: =IFERROR(N7/O7,0) -> 0.010348071
A8: 12820107 | B8: S:t Olov | C8: 1138 | D8: 76.27 | E8: 75.38 | F8: 300 | G8: 126 | H8: 128 | I8: 127 | J8: 69 | K8: 31 | L8: 42 | M8: 22 | N8: 7 | O8: =SUM(F8:N8) -> 852 | P8: =IFERROR(F8/O8,0) -> 0.35211268 | Q8: =IFERROR(G8/O8,0) -> 0.14788732 | R8: =IFERROR(H8/O8,0) -> 0.15023474 | S8: =IFERROR(I8/O8,0) -> 0.14906103 | T8: =IFERROR(J8/O8,0) -> 0.080985915 | U8: =IFERROR(K8/O8,0) -> 0.036384977 | V8: =IFERROR(L8/O8,0) -> 0.049295775 | W8: =IFERROR(M8/O8,0) -> 0.025821596 | X8: =IFERROR(N8/O8,0) -> 0.0082159624
A9: 12820108 | B9: Albano | C9: 1725 | D9: 65.22 | E9: 62.31 | F9: 444 | G9: 224 | H9: 106 | I9: 80 | J9: 121 | K9: 51 | L9: 41 | M9: 23 | N9: 11 | O9: =SUM(F9:N9) -> 1101 | P9: =IFERROR(F9/O9,0) -> 0.40326975 | Q9: =IFERROR(G9/O9,0) -> 0.20345141 | R9: =IFERROR(H9/O9,0) -> 0.096276113 | S9: =IFERROR(I9/O9,0) -> 0.072661217 | T9: =IFERROR(J9/O9,0) -> 0.10990009 | U9: =IFERROR(K9/O9,0) -> 0.046321526 | V9: =IFERROR(L9/O9,0) -> 0.037238874 | W9: =IFERROR(M9/O9,0) -> 0.0208901 | X9: =IFERROR(N9/O9,0) -> 0.0099909173
A10: 12820109 | B10: Larvi | C10: 1510 | D10: 74.5 | E10: 73.26 | F10: 384 | G10: 253 | H10: 155 | I10: 104 | J10: 86 | K10: 58 | L10: 38 | M10: 15 | N10: 2 | O10: =SUM(F10:N10) -> 1095 | P10: =IFERROR(F10/O10,0) -> 0.35068493 | Q10: =IFERROR(G10/O10,0) -> 0.23105023 | R10: =IFERROR(H10/O10,0) -> 0.14155251 | S10: =IFERROR(I10/O10,0) -> 0.094977169 | T10: =IFERROR(J10/O10,0) -> 0.078538813 | U10: =IFERROR(K10/O10,0) -> 0.052968037 | V10: =IFERROR(L10/O10,0) -> 0.034703196 | W10: =IFERROR(M10/O10,0) -> 0.01369863 | X10: =IFERROR(N10/O10,0) -> 0.001826484
A11: 12820110 | B11: Sandvången | C11: 1040 | D11: 75.87 | E11: 75.57 | F11: 283 | G11: 226 | H11: 94 | I11: 53 | J11: 63 | K11: 27 | L11: 14 | M11: 3 | N11: 7 | O11: =SUM(F11:N11) -> 770 | P11: =IFERROR(F11/O11,0) -> 0.36753247 | Q11: =IFERROR(G11/O11,0) -> 0.29350649 | R11: =IFERROR(H11/O11,0) -> 0.12207792 | S11: =IFERROR(I11/O11,0) -> 0.068831169 | T11: =IFERROR(J11/O11,0) -> 0.081818182 | U11: =IFERROR(K11/O11,0) -> 0.035064935 | V11: =IFERROR(L11/O11,0) -> 0.018181818 | W11: =IFERROR(M11/O11,0) -> 0.0038961039 | X11: =IFERROR(N11/O11,0) -> 0.0090909091
A12: 12820111 | B12: Helgebröten | C12: 1161 | D12: 77.86 | E12: 80.16 | F12: 402 | G12: 113 | H12: 118 | I12: 98 | J12: 75 | K12: 52 | L12: 23 | M12: 13 | N12: 2 | O12: =SUM(F12:N12) -> 896 | P12: =IFERROR(F12/O12,0) -> 0.44866071 | Q12: =IFERROR(G12/O12,0) -> 0.12611607 | R12: =IFERROR(H12/O12,0) -> 0.13169643 | S12: =IFERROR(I12/O12,0) -> 0.109375 | T12: =IFERROR(J12/O12,0) -> 0.083705357 | U12: =IFERROR(K12/O12,0) -> 0.058035714 | V12: =IFERROR(L12/O12,0) -> 0.025669643 | W12: =IFERROR(M12/O12,0) -> 0.014508929 | X12: =IFERROR(N12/O12,0) -> 0.0022321429
A13: 12820112 | B13: Norrestad | C13: 1742 | D13: 60.16 | E13: 54.51 | F13: 474 | G13: 119 | H13: 49 | I13: 36 | J13: 310 | K13: 9 | L13: 27 | M13: 8 | N13: 7 | O13: =SUM(F13:N13) -> 1039 | P13: =IFERROR(F13/O13,0) -> 0.45620789 | Q13: =IFERROR(G13/O13,0) -> 0.11453321 | R13: =IFERROR(H13/O13,0) -> 0.047160731 | S13: =IFERROR(I13/O13,0) -> 0.034648701 | T13: =IFERROR(J13/O13,0) -> 0.29836381 | U13: =IFERROR(K13/O13,0) -> 0.0086621752 | V13: =IFERROR(L13/O13,0) -> 0.025986526 | W13: =IFERROR(M13/O13,0) -> 0.0076997113 | X13: =IFERROR(N13/O13,0) -> 0.0067372474
... A27: 12820803 | B27: Glumslöv Södra | C27: 1001 | D27: 88.31 | E27: 88.26 | F27: 198 | G27: 136 | H27: 242 | I27: 115 | J27: 20 | K27: 62 | L27: 33 | M27: 58 | N27: 3 | O27: =SUM(F27:N27) -> 867 | P27: =IFERROR(F27/O27,0) -> 0.2283737 | Q27: =IFERROR(G27/O27,0) -> 0.15686275 | R27: =IFERROR(H27/O27,0) -> 0.27912341 | S27: =IFERROR(I27/O27,0) -> 0.13264129 | T27: =IFERROR(J27/O27,0) -> 0.023068051 | U27: =IFERROR(K27/O27,0) -> 0.071510957 | V27: =IFERROR(L27/O27,0) -> 0.038062284 | W27: =IFERROR(M27/O27,0) -> 0.066897347 | X27: =IFERROR(N27/O27,0) -> 0.0034602076
A28: 128200 | B28: Uppsamlingsdistrikt 00 | F28: 244 | G28: 145 | H28: 145 | I28: 75 | J28: 86 | K28: 28 | L28: 31 | M28: 25 | N28: 7 | O28: =SUM(F28:N28) -> 786 | P28: =IFERROR(F28/O28,0) -> 0.31043257 | Q28: =IFERROR(G28/O28,0) -> 0.18447837 | R28: =IFERROR(H28/O28,0) -> 0.18447837 | S28: =IFERROR(I28/O28,0) -> 0.095419847 | T28: =IFERROR(J28/O28,0) -> 0.10941476 | U28: =IFERROR(K28/O28,0) -> 0.03562341 | V28: =IFERROR(L28/O28,0) -> 0.039440204 | W28: =IFERROR(M28/O28,0) -> 0.031806616 | X28: =IFERROR(N28/O28,0) -> 0.0089058524
B29: Landskrona totalt | C29: =SUM(C2:C28) -> 37352 | F29: =SUM(F2:F28) -> 9403 | G29: =SUM(G2:G28) -> 5137 | H29: =SUM(H2:H28) -> 5049 | I29: =SUM(I2:I28) -> 3146 | J29: =SUM(J2:J28) -> 2563 | K29: =SUM(K2:K28) -> 1341 | L29: =SUM(L2:L28) -> 934 | M29: =SUM(M2:M28) -> 686 | ... O29: =SUM(O2:O28) -> 28457 | P29: =F29/O29 -> 0.33042837 | Q29: =G29/O29 -> 0.18051797 | R29: =H29/O29 -> 0.17742559 | S29: =I29/O29 -> 0.11055276 | T29: =J29/O29 -> 0.090065713 | U29: =K29/O29 -> 0.047123731 | V29: =L29/O29 -> 0.03282145 | W29: =M29/O29 -> 0.024106547 | X29: =N29/O29 -> 0.0069578663

Sheet RD 2026
A1: Distriktskod | B1: Distrikt | C1: Röstberättigade | D1: Valdeltagande 2026 (%) | E1: Valdeltagande 2022 (%) | F1: S | G1: SD | H1: M | I1: V | J1: L | K1: KD | L1: C | M1: MP | N1: Övr | O1: Giltiga röster | P1: S % | Q1: SD % | R1: M % | S1: V % | T1: L % | U1: KD % | V1: C % | W1: MP % | X1: Övr %
A2: 12820101 | B2: Citadellstaden | C2: 1524 | D2: 75.52 | E2: 82.37 | F2: 317 | G2: 317 | H2: 185 | I2: 71 | J2: 120 | K2: 42 | L2: 41 | M2: 30 | N2: 13 | O2: =SUM(F2:N2) -> 1136 | P2: =IFERROR(F2/O2,0) -> 0.2790493 | Q2: =IFERROR(G2/O2,0) -> 0.2790493 | R2: =IFERROR(H2/O2,0) -> 0.16285211 | S2: =IFERROR(I2/O2,0) -> 0.0625 | T2: =IFERROR(J2/O2,0) -> 0.1056338 | U2: =IFERROR(K2/O2,0) -> 0.036971831 | V2: =IFERROR(L2/O2,0) -> 0.036091549 | W2: =IFERROR(M2/O2,0) -> 0.026408451 | X2: =IFERROR(N2/O2,0) -> 0.011443662
A3: 12820102 | B3: Fröjdenborg | C3: 1479 | D3: 75.79 | E3: 73.37 | F3: 332 | G3: 282 | H3: 131 | I3: 131 | J3: 101 | K3: 34 | L3: 37 | M3: 50 | N3: 11 | O3: =SUM(F3:N3) -> 1109 | P3: =IFERROR(F3/O3,0) -> 0.2993688 | Q3: =IFERROR(G3/O3,0) -> 0.25428314 | R3: =IFERROR(H3/O3,0) -> 0.11812444 | S3: =IFERROR(I3/O3,0) -> 0.11812444 | T3: =IFERROR(J3/O3,0) -> 0.091073039 | U3: =IFERROR(K3/O3,0) -> 0.030658251 | V3: =IFERROR(L3/O3,0) -> 0.03336339 | W3: =IFERROR(M3/O3,0) -> 0.045085663 | X3: =IFERROR(N3/O3,0) -> 0.0099188458
A4: 12820103 | B4: Norra Förstaden | C4: 1625 | D4: 68.18 | E4: 66.73 | F4: 415 | G4: 227 | H4: 110 | I4: 171 | J4: 61 | K4: 21 | L4: 22 | M4: 52 | N4: 18 | O4: =SUM(F4:N4) -> 1097 | P4: =IFERROR(F4/O4,0) -> 0.37830447 | Q4: =IFERROR(G4/O4,0) -> 0.20692799 | R4: =IFERROR(H4/O4,0) -> 0.10027347 | S4: =IFERROR(I4/O4,0) -> 0.15587967 | T4: =IFERROR(J4/O4,0) -> 0.055606199 | U4: =IFERROR(K4/O4,0) -> 0.019143118 | V4: =IFERROR(L4/O4,0) -> 0.020054695 | W4: =IFERROR(M4/O4,0) -> 0.047402005 | X4: =IFERROR(N4/O4,0) -> 0.016408387
A5: 12820104 | B5: Centrum | C5: 1640 | D5: 70.24 | E5: 66.79 | F5: 370 | G5: 269 | H5: 159 | I5: 117 | J5: 83 | K5: 41 | L5: 31 | M5: 46 | N5: 22 | O5: =SUM(F5:N5) -> 1138 | P5: =IFERROR(F5/O5,0) -> 0.32513181 | Q5: =IFERROR(G5/O5,0) -> 0.23637961 | R5: =IFERROR(H5/O5,0) -> 0.1397188 | S5: =IFERROR(I5/O5,0) -> 0.10281195 | T5: =IFERROR(J5/O5,0) -> 0.072934974 | U5: =IFERROR(K5/O5,0) -> 0.03602812 | V5: =IFERROR(L5/O5,0) -> 0.027240773 | W5: =IFERROR(M5/O5,0) -> 0.040421793 | X5: =IFERROR(N5/O5,0) -> 0.019332162
A6: 12820105 | B6: Dammhagen | C6: 1416 | D6: 65.32 | E6: 60.49 | F6: 398 | G6: 150 | H6: 68 | I6: 203 | J6: 30 | K6: 14 | L6: 14 | M6: 26 | N6: 13 | O6: =SUM(F6:N6) -> 916 | P6: =IFERROR(F6/O6,0) -> 0.43449782 | Q6: =IFERROR(G6/O6,0) -> 0.16375546 | R6: =IFERROR(H6/O6,0) -> 0.074235808 | S6: =IFERROR(I6/O6,0) -> 0.22161572 | T6: =IFERROR(J6/O6,0) -> 0.032751092 | U6: =IFERROR(K6/O6,0) -> 0.015283843 | V6: =IFERROR(L6/O6,0) -> 0.015283843 | W6: =IFERROR(M6/O6,0) -> 0.028384279 | X6: =IFERROR(N6/O6,0) -> 0.01419214
A7: 12820106 | B7: Gustav Adolf | C7: 1530 | D7: 66.47 | E7: 61.76 | F7: 408 | G7: 185 | H7: 103 | I7: 180 | J7: 41 | K7: 27 | L7: 14 | M7: 32 | N7: 19 | O7: =SUM(F7:N7) -> 1009 | P7: =IFERROR(F7/O7,0) -> 0.40436075 | Q7: =IFERROR(G7/O7,0) -> 0.18334985 | R7: =IFERROR(H7/O7,0) -> 0.10208127 | S7: =IFERROR(I7/O7,0) -> 0.17839445 | T7: =IFERROR(J7/O7,0) -> 0.040634291 | U7: =IFERROR(K7/O7,0) -> 0.026759167 | V7: =IFERROR(L7/O7,0) -> 0.013875124 | W7: =IFERROR(M7/O7,0) -> 0.031714569 | X7: =IFERROR(N7/O7,0) -> 0.018830525
A8: 12820107 | B8: S:t Olov | C8: 1091 | D8: 78.19 | E8: 77.35 | F8: 262 | G8: 171 | H8: 119 | I8: 67 | J8: 88 | K8: 27 | L8: 48 | M8: 49 | N8: 13 | O8: =SUM(F8:N8) -> 844 | P8: =IFERROR(F8/O8,0) -> 0.31042654 | Q8: =IFERROR(G8/O8,0) -> 0.20260664 | R8: =IFERROR(H8/O8,0) -> 0.14099526 | S8: =IFERROR(I8/O8,0) -> 0.079383886 | T8: =IFERROR(J8/O8,0) -> 0.1042654 | U8: =IFERROR(K8/O8,0) -> 0.031990521 | V8: =IFERROR(L8/O8,0) -> 0.056872038 | W8: =IFERROR(M8/O8,0) -> 0.058056872 | X8: =IFERROR(N8/O8,0) -> 0.015402844
A9: 12820108 | B9: Albano | C9: 1597 | D9: 69.32 | E9: 65.7 | F9: 410 | G9: 265 | H9: 103 | I9: 120 | J9: 65 | K9: 39 | L9: 30 | M9: 41 | N9: 19 | O9: =SUM(F9:N9) -> 1092 | P9: =IFERROR(F9/O9,0) -> 0.37545788 | Q9: =IFERROR(G9/O9,0) -> 0.24267399 | R9: =IFERROR(H9/O9,0) -> 0.094322344 | S9: =IFERROR(I9/O9,0) -> 0.10989011 | T9: =IFERROR(J9/O9,0) -> 0.05952381 | U9: =IFERROR(K9/O9,0) -> 0.035714286 | V9: =IFERROR(L9/O9,0) -> 0.027472527 | W9: =IFERROR(M9/O9,0) -> 0.037545788 | X9: =IFERROR(N9/O9,0) -> 0.017399267
A10: 12820109 | B10: Larvi | C10: 1428 | D10: 78.08 | E10: 77.26 | F10: 346 | G10: 314 | H10: 149 | I10: 82 | J10: 71 | K10: 48 | L10: 28 | M10: 46 | N10: 10 | O10: =SUM(F10:N10) -> 1094 | P10: =IFERROR(F10/O10,0) -> 0.31627057 | Q10: =IFERROR(G10/O10,0) -> 0.28702011 | R10: =IFERROR(H10/O10,0) -> 0.13619744 | S10: =IFERROR(I10/O10,0) -> 0.074954296 | T10: =IFERROR(J10/O10,0) -> 0.064899452 | U10: =IFERROR(K10/O10,0) -> 0.043875686 | V10: =IFERROR(L10/O10,0) -> 0.02559415 | W10: =IFERROR(M10/O10,0) -> 0.042047532 | X10: =IFERROR(N10/O10,0) -> 0.0091407678
A11: 12820110 | B11: Sandvången | C11: 1001 | D11: 77.72 | E11: 78.69 | F11: 267 | G11: 265 | H11: 82 | I11: 69 | J11: 29 | K11: 25 | L11: 5 | M11: 16 | N11: 9 | O11: =SUM(F11:N11) -> 767 | P11: =IFERROR(F11/O11,0) -> 0.34810952 | Q11: =IFERROR(G11/O11,0) -> 0.34550196 | R11: =IFERROR(H11/O11,0) -> 0.10691004 | S11: =IFERROR(I11/O11,0) -> 0.089960887 | T11: =IFERROR(J11/O11,0) -> 0.037809648 | U11: =IFERROR(K11/O11,0) -> 0.032594524 | V11: =IFERROR(L11/O11,0) -> 0.0065189048 | W11: =IFERROR(M11/O11,0) -> 0.020860495 | X11: =IFERROR(N11/O11,0) -> 0.011734029
